Workbook
Name BASE_AN: Rates!$B$4
Name BASE_CL: Rates!$B$5
Name RCF_AN: Rates!$B$1
Name RCF_CL: Rates!$B$2
Name VAT: Rates!$B$3

Sheet Rates
A1: RCF_AN | B1: 283.856
A2: RCF_CL | B2: 39.982
A3: VAT | B3: 0.15
A4: BASE_AN | B4: 139.1451
A5: BASE_CL | B5: 19.59902
A7: Code | B7: Description | C7: RVU | D7: BaseAmount | E7: SpecialtyIndex
A8: 0227 | B8: Special treatment of severe acne cases, including draining of cysts, e | C8: 4 | D8: 1135.4 | E8: 10
A9: 0233 | B9: Biopsy without suturing: First lesion | C9: 3 | D9: 851.6 | E9: 10
A10: 0234 | B10: Biopsy without suturing: Subsequent lesions (each) | C10: 3 | D10: 851.6 | E10: 10
A11: 0235 | B11: Biopsy without suturing: Maximum for multiple additional lesions | C11: 3 | D11: 851.6 | E11: 10
A12: 0237 | B12: Deep skin biopsy by surgical incision with local anaesthetic and sutur | C12: 3 | D12: 851.6 | E12: 10
A13: 0241 | B13: Treatment of benign skin lesion by chemo-cryotherapy: First Lesion | C13: 3 | D13: 851.6 | E13: 10
A14: 0242 | B14: Treatment of benign skin lesion by chemo-cryotherapy: Subsequent lesio | C14: 3 | D14: 851.6 | E14: 10
A15: 0243 | B15: Treatment of benign skin lesion by chemo-cryotherapy: Maximum for mult | C15: 3 | D15: 851.6 | E15: 10
A16: 0244 | B16: Repair of nail bed | C16: 3 | D16: 851.6 | E16: 10
A17: 0245 | B17: Removal of benign lesion by curretting under local or general anaesthe | C17: 3 | D17: 851.6 | E17: 10
A18: 0246 | B18: Removal of benign lesion by curretting under local or general anaesthe | C18: 3 | D18: 851.6 | E18: 10
A19: 0251 | B19: Removal of malignant lesions by curretting under local or general anae | C19: 3 | D19: 851.6 | E19: 10
... A1271: 1085A | B1271: Total reconstruction of the nose: Including reconstruction of nasal se | C1271: 5 | D1271: 1419.3 | E1271: 1
A1273: PlanID | B1273: Label | C1273: Multiplier | D1273: Loc
A1274: classic_ih | B1274: Classic Direct (In-Hospital) | C1274: 2.04 | D1274: ih
A1275: classic_oh | B1275: Classic Direct (Day Case / OH) | C1275: 2.3 | D1275: oh
A1276: executive | B1276: Executive | C1276: 3 | D1276: ih
A1277: essential | B1277: Essential / Coastal | C1277: 2 | D1277: ih
A1278: other_ma | B1278: Other Medical Aids | C1278: 2.14 | D1278: ih
A1280: ModCode | B1280: Description | C1280: Units | D1280: UnitType | E1280: Category
A1281: 43 | B1281: Age < 1 year or > 70 years | C1281: 3 | D1281: an | E1281: Patient
A1282: 34 | B1282: Head and Neck procedure | C1282: 5 | D1282: an | E1282: Procedure
A1283: 18 | B1283: BMI modifier | C1283: 0 | D1283: an | E1283: Patient
A1284: 1215 | B1284: Arterial line (A-line) | C1284: 25 | D1284: cl | E1284: Monitoring
A1285: 1218 | B1285: Central Venous Pressure (CVP) | C1285: 25 | D1285: cl | E1285: Monitoring
A1286: 1217 | B1286: CVP - Long line (peripheral) | C1286: 10 | D1286: cl | E1286: Monitoring
A1287: 2799 | B1287: Spinal anaesthesia (intrathecal) | C1287: 4 | D1287: an | E1287: Regional
A1288: 2800 | B1288: Plexus block | C1288: 36 | D1288: cl | E1288: Regional
A1289: 2801 | B1289: Epidural | C1289: 36 | D1289: cl | E1289: Regional
A1290: 2802 | B1290: Peripheral nerve block | C1290: 25 | D1290: cl | E1290: Regional
A1291: 1780 | B1291: Nasogastric tube insertion | C1291: 8 | D1291: cl | E1291: Procedure
A1292: 1807 | B1292: Laparoscope modifier | C1292: 5 | D1292: an | E1292: Procedure
A1293: 1221 | B1293: PCA pump (first 24 hours) | C1293: 30 | D1293: cl | E1293: Procedure
A1295: ConsCode | B1295: Description | C1295: IH | D1295: OH
...

Sheet Input
A1: Patient | B1: John Shirley
A2: ICD-10 | B2: K01.1
A3: Surgeon | B3: Dr N Vafaei )pr. 0662747)
A5: Rate Plan | B5: Classic Direct (Day Case / OH)
A7: Procedure Code | B7: 0285 | C7: =IF(B7="","",VLOOKUP(B7, Rates!$A$8:$B$1271, 2, FALSE)) -> Laser treatment for large skin lesions: Whole face or other areas of e
A9: Anaesthetic Minutes | B9: 53
A11: Emergency? (Yes/No) | B11: No | C11: Emergency Minutes
A13: Consult 1 | B13: 151
A14: Consult 2 | B14: 146
A15: Consult 3
A17: Modifier Code | B17: Enabled (Yes/No)
A18: 43 | B18: Yes
A19: 34 | B19: Yes
B20: No
B21: No
B22: No
B23: No
B24: No
B25: No
B26: No
B27: No
B28: No
B29: No
B30: No
B31: No
... B37: No

Sheet Calculations
A1: Plan Multiplier | B1: =IF(Input!B5="","",INDEX(Rates!$C$1274:$C$1278,MATCH(Input!B5,Rates!$B$1274:$B$1278,0))) -> 2.3
A2: Plan Location | B2: =IF(Input!B5="","",INDEX(Rates!$D$1274:$D$1278,MATCH(Input!B5,Rates!$B$1274:$B$1278,0))) -> oh
A3: Proc RVU | B3: =IF(Input!B7="","",VLOOKUP(Input!B7, Rates!$A$8:$C$1271,3,FALSE)) -> 4
A4: Proc UnitPrice_exclVAT | B4: =IF(B3="","",(B3*BASE_AN*B1)/(1+VAT)) -> 1113.1608
A6: Anaes Minutes | B6: =IF(Input!B9="",0,Input!B9) -> 53
A7: Has BMI | B7: =IF(COUNTIFS(Input!$A$18:$A$37,"18",Input!$B$18:$B$37,"Yes")>0,1,0) -> 0
A8: Effective Minutes | B8: =IF(B7=1,ROUND(B6*1.5,0),B6) -> 53
A9: Time Units | B9: =IF(B8<=0,0,IF(B8<=60,CEILING(B8/15,1)*2,8+CEILING((B8-60)/15,1)*3)) -> 8
A10: Anaes Unit Price exclVAT | B10: =IF(B1="","",(BASE_AN*B1)/(1+VAT)) -> 278.2902
A11: Anaes Amount exclVAT | B11: =B9*B10 -> 2226.3216
A13: Emergency Minutes | B13: =IF(Input!B11="Yes",Input!D11,0) -> 0
A14: Emergency Blocks | B14: =IF(B13<=0,0,CEILING(B13/30,1)) -> 0
A15: Clinical unit price exclVAT | B15: =(BASE_CL*B1)/(1+VAT) -> 39.198039
A16: Emergency Unit Price per block exclVAT | B16: =B15*12 -> 470.37647
A17: Emergency Amount exclVAT | B17: =B14*B16 -> 0
A20: Modifiers Amount exclVAT | B20: =SUMPRODUCT( (COUNTIF(Input!$A$18:$A$37, Rates!$A$1281:$A$1293)>0) * ( Rates!$C$1281:$C$1293 * (((Rates!$D$1281:$D$1293="an")*BASE_AN) + ((Rates!$D$1281:$D$1293="cl")*BASE_CL)) * B1 / (1+VAT) ) ) -> 2226.3216

Sheet Output
A1: Anaesthetic Quote (2026) | H1: Workings
A2: Patient | B2: =Input!B1 -> John Shirley | C2: ICD-10 | D2: =Input!B2 -> K01.1 | E2: Plan | F2: =Input!B5 -> Classic Direct (Day Case / OH) | H2: Plan Multiplier | I2: =Calculations!B1 -> 2.3
A3: Surgeon | B3: =Input!B3 -> Dr N Vafaei )pr. 0662747) | C3: Procedure | D3: =Input!B7 -> 0285 | E3: Minutes | F3: =Input!B9 -> 53 | H3: Plan Location | I3: =Calculations!B2 -> oh
H4: Proc RVU | I4: =Calculations!B3 -> 4
A5: Code | B5: Description | C5: Qty | D5: Unit Price exclVAT | E5: VAT% | F5: Amount exclVAT | H5: Proc Unit Price (ex VAT) | I5: =Calculations!B4 -> 1113.1608
A6: =IF(Input!B13="","",Input!B13) -> 151 | B6: =IF(Input!B13="","",VLOOKUP(Input!B13, Rates!$A$1295:$B$1307,2,FALSE)) -> Pre-anaesthetic Assessment | C6: =IF(Input!B13="",0,1) -> 1 | D6: =IF(Input!B13="",0,IF(Calculations!B2="IH",VLOOKUP(Input!B13, Rates!$A$1295:$D$1307,3,FALSE),VLOOKUP(Input!B13, Rates!$A$1295:$D$1307,4,FALSE))/(1+VAT)) -> 443.47826 | E6: 15% | F6: =C6*D6 -> 443.47826 | H6: Anaes Minutes | I6: =Calculations!B6 -> 53
A7: =IF(Input!B14="","",Input!B14) -> 146 | B7: =IF(Input!B14="","",VLOOKUP(Input!B14, Rates!$A$1295:$B$1307,2,FALSE)) -> Emergency Consult (at rooms) | C7: =IF(Input!B14="",0,1) -> 1 | D7: =IF(Input!B14="",0,IF(Calculations!B2="IH",VLOOKUP(Input!B14, Rates!$A$1295:$D$1307,3,FALSE),VLOOKUP(Input!B14, Rates!$A$1295:$D$1307,4,FALSE))/(1+VAT)) -> 208.95652 | E7: 15% | F7: =C7*D7 -> 208.95652 | H7: Effective Minutes | I7: =Calculations!B8 -> 53
A8: =IF(Input!B15="","",Input!B15) | B8: =IF(Input!B15="","",VLOOKUP(Input!B15, Rates!$A$1295:$B$1307,2,FALSE)) | C8: =IF(Input!B15="",0,1) -> 0 | D8: =IF(Input!B15="",0,IF(Calculations!B2="IH",VLOOKUP(Input!B15, Rates!$A$1295:$D$1307,3,FALSE),VLOOKUP(Input!B15, Rates!$A$1295:$D$1307,4,FALSE))/(1+VAT)) -> 0 | E8: 15% | F8: =C8*D8 -> 0 | H8: Time Units | I8: =Calculations!B9 -> 8
A9: =IF(Input!B7="","",Input!B7) -> 0285 | B9: =IF(Input!B7="","",VLOOKUP(Input!B7, Rates!$A$8:$B$1271,2,FALSE)) -> Laser treatment for large skin lesions: Whole face or other areas of e | C9: =IF(Input!B7="",0,1) -> 1 | D9: =IF(Calculations!B4="",0,Calculations!B4) -> 1113.1608 | E9: 15% | F9: =C9*D9 -> 1113.1608 | H9: Anaes Unit Price (ex VAT) | I9: =Calculations!B10 -> 278.2902
A10: 0023 | B10: =IF(Calculations!B9=0,"",_xlfn.CONCAT("Anaesthetic time ",Input!B9," min")) -> Anaesthetic time 53 min | C10: =Calculations!B9 -> 8 | D10: =Calculations!B10 -> 278.2902 | E10: 15% | F10: =C10*D10 -> 2226.3216 | H10: Emergency Blocks | I10: =Calculations!B14 -> 0
A11: 11 | B11: =IF(Calculations!B14=0,"",_xlfn.CONCAT("Emergency ",Input!D11," min")) | C11: =Calculations!B14 -> 0 | D11: =Calculations!B16 -> 470.37647 | E11: 15% | F11: =C11*D11 -> 0 | H11: Emergency Block Price (ex VAT) | I11: =Calculations!B16 -> 470.37647
A12: MODS | B12: Modifiers (total) | C12: =IF(Calculations!B20=0,0,1) -> 1 | D12: =IF(Calculations!B20=0,0,Calculations!B20) -> 2226.3216 | E12: 15% | F12: =D12 -> 2226.3216 | H12: Modifiers Amount (ex VAT) | I12: =Calculations!B20 -> 2226.3216
E14: Subtotal (excl VAT) | F14: =SUM(F6:F12) -> 6218.2387
E15: VAT (15%) | F15: =F14*VAT -> 932.73581
E16: Total (incl VAT) | F16: =F14+F15 -> 7150.9745
